Workbook

Sheet Leia-me
A1: Kit Fase 0 — Diagnóstico do Departamento Fiscal
A2: Projeto: Ecossistema de Automação Fiscal (Domínio Web) · versão 1.0 · setembro/2026
A4: PARA QUE SERVE
A5: Objetivo | B5: Medir o ponto de partida (baseline) e organizar os dados mestres antes de automatizar. Sem esses números não dá para priorizar nem provar a redução de mão de obra.
A6: Quando usar | B6: Nas 4 semanas da Fase 0. O levantamento de tempo dura 10 dias úteis; o cadastro mestre deve cobrir 100% das empresas.
A7: ORDEM DE PREENCHIMENTO
A8: Passo 1 — Equipe | B8: Liste os analistas do fiscal. Os nomes alimentam as listas das outras abas.
A9: Passo 2 — Cadastro Mestre | B9: Uma linha por empresa (cada analista preenche a sua carteira). A classe A/B/C é sugerida automaticamente.
A10: Passo 3 — Levantamento de Tempo | B10: Cada analista registra suas atividades por 10 dias úteis (blocos de 15 min ou mais), escolhendo uma das 7 etapas.
A11: Passo 4 — Resumo Baseline | B11: Calcula sozinho: horas por etapa, % de retrabalho, horas por empresa e por classe. Informe os dias úteis medidos.
A12: Passo 5 — Business Case | B12: Troque as premissas (amarelo, texto azul) pelos números reais e escolha o cenário. Mostra FTE liberado, custo e payback.
A13: Passo 6 — Catálogo de Auditorias | B13: 46 cruzamentos priorizados por fase. Use as colunas Status/Responsável para acompanhar a construção.
A14: Passo 7 — Plano 30 dias e Roteiro | B14: Checklist da Fase 0 e perguntas para Thomson Reuters, SERPRO e fornecedores.
A15: LEGENDA DE CORES
A16: Fundo amarelo claro | B16: Célula para você preencher.
A17: Texto azul + fundo amarelo | B17: Premissa editável do Business Case (estimativa inicial; substitua pelo número real).
A18: Texto preto | B18: Fórmula. Não sobrescreva.
A19: Texto verde | B19: Vínculo com outra aba.
A20: Linha em cinza itálico | B20: EXEMPLO de preenchimento. Substitua ou apague antes de usar os resultados.
A21: AS 7 ETAPAS DO TRABALHO FISCAL
A22: 1. Coleta e cobrança de documentos | B22: Baixar XML e relatórios, cobrar o cliente, organizar pastas, receber documentos.
A23: 2. Importação e escrituração | B23: Importar XML/TXT na Domínio, lançar notas manualmente, configurar acumuladores e produtos, corrigir erros de importação.
A24: 3. Conferência e auditoria | B24: Conferir notas × escrita, CFOP/CST, totais, relatórios de conferência e cruzamentos.
A25: 4. Apuração e guias | B25: Calcular tributos na Domínio, recalcular, emitir guias (DAS, DARF, estaduais, ISS).
A26: 5. Obrigações acessórias | B26: Gerar, validar e transmitir SPEDs, PGDAS-D, DCTFWeb/MIT, EFD-Reinf e declarações estaduais/municipais.
A27: 6. Atendimento e envio ao cliente | B27: Enviar guias e relatórios, responder dúvidas, reuniões com clientes.
A28: 7. Outros | B28: Reuniões internas, treinamento, suporte de TI, tarefas não fiscais.
A29: CLASSES DE EMPRESA
A30: A — complexa | B30: Lucro Real, indústria ou mais de 500 documentos/mês.
A31: B — intermediária | B31: Lucro Presumido, sujeita a ST ou 100 a 500 documentos/mês.
A32: C — simples | B32: Demais casos (Simples Nacional de baixo volume, serviços, MEI).
A33: CUIDADOS
A34: LGPD e sigilo | B34: Esta planilha tem dados de clientes e, na aba Equipe, custos de pessoal. Guarde em pasta com acesso restrito aos sócios e à coordenação.
A35: Honestidade dos registros | B35: O levantamento de tempo não é avaliação individual. Ele mostra onde o processo trava. Diga isso à equipe antes de começar.

Sheet Equipe
A1: Equipe do departamento fiscal
A2: Os nomes desta aba alimentam as listas do Cadastro Mestre e do Levantamento de Tempo. Custo é opcional e confidencial.
A4: Nome | B4: Cargo | C4: Função atual (texto livre) | D4: Custo mensal total (R$) | E4: Perfil técnico | F4: Interesse em automação?
A5: Maria Exemplo (EXEMPLO) | B5: Analista | C5: Carteira Simples Nacional — comércio | D5: 5200 | E5: Excel avançado / Power Query | F5: S
C26: Custo médio informado (R$) | D26: =IFERROR(AVERAGE(D6:D24),0) -> 0

Sheet Cadastro Mestre
A1: Cadastro Mestre de Empresas
A2: Uma linha por empresa. Colunas (auto) são fórmulas. A classe final usa o ajuste manual, se houver.
A4: Cód. Domínio | B4: CNPJ | C4: Razão social | D4: Regime | E4: Atividade | F4: UF | G4: Município | H4: Contribuinte ICMS? | I4: Sujeita a ST? | J4: NF-e/NFC-e saída/mês | K4: NF-e entrada/mês | L4: NFS-e/mês (prest.+tomadas) | M4: CT-e/mês | N4: Documentos/mês (auto) | O4: Classe sugerida (auto) | P4: Classe — ajuste manual | Q4: Classe final (auto) | R4: Analista responsável | S4: Certificado | T4: Validade do certificado | U4: Dias p/ vencer (auto) | V4: Procuração e-CAC ao escritório? | W4: Validade da procuração | X4: PGDAS-D/DEFIS | Y4: DCTFWeb/MIT | Z4: EFD-Reinf | AA4: EFD ICMS/IPI | AB4: EFD-Contrib. | AC4: Declaração estadual (qual?) | AD4: ISS/declaração municipal | AE4: Benefício fiscal / regime especial | AF4: Importa XML na Domínio hoje? | AG4: Observações
A5: 101 | B5: 00.000.000/0001-00 | C5: Comércio Exemplo Ltda (EXEMPLO) | D5: Simples Nacional | E5: Comércio | F5: SP | G5: Campinas | H5: S | I5: S | J5: 180 | K5: 95 | L5: 4 | M5: 6 | N5: =IF(C5="","",SUM(J5:M5)) -> 285 | O5: =IF(C5="","",IF(OR(D5="Lucro Real",E5="Indústria",N5>500),"A",IF(OR(D5="Lucro Presumido",I5="S",N5>=100),"B","C"))) -> B | Q5: =IF(C5="","",IF(P5<>"",P5,O5)) -> B | R5: Maria Exemplo (EXEMPLO) | S5: A1 | T5: 46461 | U5: =IF(T5="","",T5-TODAY()) -> 170 | V5: S | W5: 46630 | X5: S | Y5: S | Z5: N | AA5: N | AB5: N | AC5: DeSTDA | AD5: N | AF5: Parcial | AG5: Linha de exemplo: substitua ou apague.
N6: =IF(C6="","",SUM(J6:M6)) | O6: =IF(C6="","",IF(OR(D6="Lucro Real",E6="Indústria",N6>500),"A",IF(OR(D6="Lucro Presumido",I6="S",N6>=100),"B","C"))) | Q6: =IF(C6="","",IF(P6<>"",P6,O6)) | U6: =IF(T6="","",T6-TODAY())
N7: =IF(C7="","",SUM(J7:M7)) | O7: =IF(C7="","",IF(OR(D7="Lucro Real",E7="Indústria",N7>500),"A",IF(OR(D7="Lucro Presumido",I7="S",N7>=100),"B","C"))) | Q7: =IF(C7="","",IF(P7<>"",P7,O7)) | U7: =IF(T7="","",T7-TODAY())
N8: =IF(C8="","",SUM(J8:M8)) | O8: =IF(C8="","",IF(OR(D8="Lucro Real",E8="Indústria",N8>500),"A",IF(OR(D8="Lucro Presumido",I8="S",N8>=100),"B","C"))) | Q8: =IF(C8="","",IF(P8<>"",P8,O8)) | U8: =IF(T8="","",T8-TODAY())
N9: =IF(C9="","",SUM(J9:M9)) | O9: =IF(C9="","",IF(OR(D9="Lucro Real",E9="Indústria",N9>500),"A",IF(OR(D9="Lucro Presumido",I9="S",N9>=100),"B","C"))) | Q9: =IF(C9="","",IF(P9<>"",P9,O9)) | U9: =IF(T9="","",T9-TODAY())
N10: =IF(C10="","",SUM(J10:M10)) | O10: =IF(C10="","",IF(OR(D10="Lucro Real",E10="Indústria",N10>500),"A",IF(OR(D10="Lucro Presumido",I10="S",N10>=100),"B","C"))) | Q10: =IF(C10="","",IF(P10<>"",P10,O10)) | U10: =IF(T10="","",T10-TODAY())
N11: =IF(C11="","",SUM(J11:M11)) | O11: =IF(C11="","",IF(OR(D11="Lucro Real",E11="Indústria",N11>500),"A",IF(OR(D11="Lucro Presumido",I11="S",N11>=100),"B","C"))) | Q11: =IF(C11="","",IF(P11<>"",P11,O11)) | U11: =IF(T11="","",T11-TODAY())
N12: =IF(C12="","",SUM(J12:M12)) | O12: =IF(C12="","",IF(OR(D12="Lucro Real",E12="Indústria",N12>500),"A",IF(OR(D12="Lucro Presumido",I12="S",N12>=100),"B","C"))) | Q12: =IF(C12="","",IF(P12<>"",P12,O12)) | U12: =IF(T12="","",T12-TODAY())
N13: =IF(C13="","",SUM(J13:M13)) | O13: =IF(C13="","",IF(OR(D13="Lucro Real",E13="Indústria",N13>500),"A",IF(OR(D13="Lucro Presumido",I13="S",N13>=100),"B","C"))) | Q13: =IF(C13="","",IF(P13<>"",P13,O13)) | U13: =IF(T13="","",T13-TODAY())
N14: =IF(C14="","",SUM(J14:M14)) | O14: =IF(C14="","",IF(OR(D14="Lucro Real",E14="Indústria",N14>500),"A",IF(OR(D14="Lucro Presumido",I14="S",N14>=100),"B","C"))) | Q14: =IF(C14="","",IF(P14<>"",P14,O14)) | U14: =IF(T14="","",T14-TODAY())
N15: =IF(C15="","",SUM(J15:M15)) | O15: =IF(C15="","",IF(OR(D15="Lucro Real",E15="Indústria",N15>500),"A",IF(OR(D15="Lucro Presumido",I15="S",N15>=100),"B","C"))) | Q15: =IF(C15="","",IF(P15<>"",P15,O15)) | U15: =IF(T15="","",T15-TODAY())
N16: =IF(C16="","",SUM(J16:M16)) | O16: =IF(C16="","",IF(OR(D16="Lucro Real",E16="Indústria",N16>500),"A",IF(OR(D16="Lucro Presumido",I16="S",N16>=100),"B","C"))) | Q16: =IF(C16="","",IF(P16<>"",P16,O16)) | U16: =IF(T16="","",T16-TODAY())
N17: =IF(C17="","",SUM(J17:M17)) | O17: =IF(C17="","",IF(OR(D17="Lucro Real",E17="Indústria",N17>500),"A",IF(OR(D17="Lucro Presumido",I17="S",N17>=100),"B","C"))) | Q17: =IF(C17="","",IF(P17<>"",P17,O17)) | U17: =IF(T17="","",T17-TODAY())
... N504: =IF(C504="","",SUM(J504:M504)) | O504: =IF(C504="","",IF(OR(D504="Lucro Real",E504="Indústria",N504>500),"A",IF(OR(D504="Lucro Presumido",I504="S",N504>=100),"B","C"))) | Q504: =IF(C504="","",IF(P504<>"",P504,O504)) | U504: =IF(T504="","",T504-TODAY())

Sheet Levantamento de Tempo
A1: Levantamento de Tempo (10 dias úteis)
A2: Registre cada bloco de trabalho (mín. 15 min). Empresa e classe aparecem sozinhas a partir do código.
A4: Data | B4: Analista | C4: Cód. empresa | D4: Empresa (auto) | E4: Classe (auto) | F4: Etapa | G4: Minutos | H4: Retrabalho? | I4: Detalhe (o que foi feito)
A5: 46296 | B5: Maria Exemplo (EXEMPLO) | C5: 101 | D5: =IF(C5="","",IFERROR(INDEX('Cadastro Mestre'!$C$5:$C$504,MATCH(C5,'Cadastro Mestre'!$A$5:$A$504,0)),"código não encontrado")) -> Comércio Exemplo Ltda (EXEMPLO) | E5: =IF(C5="","",IFERROR(INDEX('Cadastro Mestre'!$Q$5:$Q$504,MATCH(C5,'Cadastro Mestre'!$A$5:$A$504,0)),"")) -> B | F5: 2. Importação e escrituração | G5: 45 | H5: S | I5: Reimportação de 12 XML com acumulador errado (EXEMPLO)
D6: =IF(C6="","",IFERROR(INDEX('Cadastro Mestre'!$C$5:$C$504,MATCH(C6,'Cadastro Mestre'!$A$5:$A$504,0)),"código não encontrado")) | E6: =IF(C6="","",IFERROR(INDEX('Cadastro Mestre'!$Q$5:$Q$504,MATCH(C6,'Cadastro Mestre'!$A$5:$A$504,0)),""))
D7: =IF(C7="","",IFERROR(INDEX('Cadastro Mestre'!$C$5:$C$504,MATCH(C7,'Cadastro Mestre'!$A$5:$A$504,0)),"código não encontrado")) | E7: =IF(C7="","",IFERROR(INDEX('Cadastro Mestre'!$Q$5:$Q$504,MATCH(C7,'Cadastro Mestre'!$A$5:$A$504,0)),""))
D8: =IF(C8="","",IFERROR(INDEX('Cadastro Mestre'!$C$5:$C$504,MATCH(C8,'Cadastro Mestre'!$A$5:$A$504,0)),"código não encontrado")) | E8: =IF(C8="","",IFERROR(INDEX('Cadastro Mestre'!$Q$5:$Q$504,MATCH(C8,'Cadastro Mestre'!$A$5:$A$504,0)),""))
D9: =IF(C9="","",IFERROR(INDEX('Cadastro Mestre'!$C$5:$C$504,MATCH(C9,'Cadastro Mestre'!$A$5:$A$504,0)),"código não encontrado")) | E9: =IF(C9="","",IFERROR(INDEX('Cadastro Mestre'!$Q$5:$Q$504,MATCH(C9,'Cadastro Mestre'!$A$5:$A$504,0)),""))
D10: =IF(C10="","",IFERROR(INDEX('Cadastro Mestre'!$C$5:$C$504,MATCH(C10,'Cadastro Mestre'!$A$5:$A$504,0)),"código não encontrado")) | E10: =IF(C10="","",IFERROR(INDEX('Cadastro Mestre'!$Q$5:$Q$504,MATCH(C10,'Cadastro Mestre'!$A$5:$A$504,0)),""))
D11: =IF(C11="","",IFERROR(INDEX('Cadastro Mestre'!$C$5:$C$504,MATCH(C11,'Cadastro Mestre'!$A$5:$A$504,0)),"código não encontrado")) | E11: =IF(C11="","",IFERROR(INDEX('Cadastro Mestre'!$Q$5:$Q$504,MATCH(C11,'Cadastro Mestre'!$A$5:$A$504,0)),""))
D12: =IF(C12="","",IFERROR(INDEX('Cadastro Mestre'!$C$5:$C$504,MATCH(C12,'Cadastro Mestre'!$A$5:$A$504,0)),"código não encontrado")) | E12: =IF(C12="","",IFERROR(INDEX('Cadastro Mestre'!$Q$5:$Q$504,MATCH(C12,'Cadastro Mestre'!$A$5:$A$504,0)),""))
D13: =IF(C13="","",IFERROR(INDEX('Cadastro Mestre'!$C$5:$C$504,MATCH(C13,'Cadastro Mestre'!$A$5:$A$504,0)),"código não encontrado")) | E13: =IF(C13="","",IFERROR(INDEX('Cadastro Mestre'!$Q$5:$Q$504,MATCH(C13,'Cadastro Mestre'!$A$5:$A$504,0)),""))
D14: =IF(C14="","",IFERROR(INDEX('Cadastro Mestre'!$C$5:$C$504,MATCH(C14,'Cadastro Mestre'!$A$5:$A$504,0)),"código não encontrado")) | E14: =IF(C14="","",IFERROR(INDEX('Cadastro Mestre'!$Q$5:$Q$504,MATCH(C14,'Cadastro Mestre'!$A$5:$A$504,0)),""))
D15: =IF(C15="","",IFERROR(INDEX('Cadastro Mestre'!$C$5:$C$504,MATCH(C15,'Cadastro Mestre'!$A$5:$A$504,0)),"código não encontrado")) | E15: =IF(C15="","",IFERROR(INDEX('Cadastro Mestre'!$Q$5:$Q$504,MATCH(C15,'Cadastro Mestre'!$A$5:$A$504,0)),""))
D16: =IF(C16="","",IFERROR(INDEX('Cadastro Mestre'!$C$5:$C$504,MATCH(C16,'Cadastro Mestre'!$A$5:$A$504,0)),"código não encontrado")) | E16: =IF(C16="","",IFERROR(INDEX('Cadastro Mestre'!$Q$5:$Q$504,MATCH(C16,'Cadastro Mestre'!$A$5:$A$504,0)),""))
D17: =IF(C17="","",IFERROR(INDEX('Cadastro Mestre'!$C$5:$C$504,MATCH(C17,'Cadastro Mestre'!$A$5:$A$504,0)),"código não encontrado")) | E17: =IF(C17="","",IFERROR(INDEX('Cadastro Mestre'!$Q$5:$Q$504,MATCH(C17,'Cadastro Mestre'!$A$5:$A$504,0)),""))
... D2004: =IF(C2004="","",IFERROR(INDEX('Cadastro Mestre'!$C$5:$C$504,MATCH(C2004,'Cadastro Mestre'!$A$5:$A$504,0)),"código não encontrado")) | E2004: =IF(C2004="","",IFERROR(INDEX('Cadastro Mestre'!$Q$5:$Q$504,MATCH(C2004,'Cadastro Mestre'!$A$5:$A$504,0)),""))

Sheet Resumo Baseline
A1: Resumo do Baseline
A2: Calculado a partir do Levantamento de Tempo e do Cadastro Mestre. Preencha só as células amarelas.
A4: Dias úteis medidos | B4: 10 | C4: Premissa: 10 dias úteis de medição (2 semanas).
A5: Dias úteis em um mês | B5: 21
A6: Fator de projeção mensal | B6: =IF(B4=0,0,B5/B4) -> 2.1
A8: Tempo por etapa
A9: Etapa | B9: Minutos no período | C9: Horas no período | D9: % do total | E9: % de retrabalho | F9: Horas/mês projetadas
A10: 1. Coleta e cobrança de documentos | B10: =SUMIFS('Levantamento de Tempo'!$G$5:$G$2004,'Levantamento de Tempo'!$F$5:$F$2004,A10) -> 0 | C10: =B10/60 -> 0 | D10: =IF($B$17=0,0,B10/$B$17) -> 0 | E10: =IF(B10=0,0,SUMIFS('Levantamento de Tempo'!$G$5:$G$2004,'Levantamento de Tempo'!$F$5:$F$2004,A10,'Levantamento de Tempo'!$H$5:$H$2004,"S")/B10) -> 0 | F10: =C10*$B$6 -> 0
A11: 2. Importação e escrituração | B11: =SUMIFS('Levantamento de Tempo'!$G$5:$G$2004,'Levantamento de Tempo'!$F$5:$F$2004,A11) -> 45 | C11: =B11/60 -> 0.75 | D11: =IF($B$17=0,0,B11/$B$17) -> 1 | E11: =IF(B11=0,0,SUMIFS('Levantamento de Tempo'!$G$5:$G$2004,'Levantamento de Tempo'!$F$5:$F$2004,A11,'Levantamento de Tempo'!$H$5:$H$2004,"S")/B11) -> 1 | F11: =C11*$B$6 -> 1.575
A12: 3. Conferência e auditoria | B12: =SUMIFS('Levantamento de Tempo'!$G$5:$G$2004,'Levantamento de Tempo'!$F$5:$F$2004,A12) -> 0 | C12: =B12/60 -> 0 | D12: =IF($B$17=0,0,B12/$B$17) -> 0 | E12: =IF(B12=0,0,SUMIFS('Levantamento de Tempo'!$G$5:$G$2004,'Levantamento de Tempo'!$F$5:$F$2004,A12,'Levantamento de Tempo'!$H$5:$H$2004,"S")/B12) -> 0 | F12: =C12*$B$6 -> 0
A13: 4. Apuração e guias | B13: =SUMIFS('Levantamento de Tempo'!$G$5:$G$2004,'Levantamento de Tempo'!$F$5:$F$2004,A13) -> 0 | C13: =B13/60 -> 0 | D13: =IF($B$17=0,0,B13/$B$17) -> 0 | E13: =IF(B13=0,0,SUMIFS('Levantamento de Tempo'!$G$5:$G$2004,'Levantamento de Tempo'!$F$5:$F$2004,A13,'Levantamento de Tempo'!$H$5:$H$2004,"S")/B13) -> 0 | F13: =C13*$B$6 -> 0
A14: 5. Obrigações acessórias | B14: =SUMIFS('Levantamento de Tempo'!$G$5:$G$2004,'Levantamento de Tempo'!$F$5:$F$2004,A14) -> 0 | C14: =B14/60 -> 0 | D14: =IF($B$17=0,0,B14/$B$17) -> 0 | E14: =IF(B14=0,0,SUMIFS('Levantamento de Tempo'!$G$5:$G$2004,'Levantamento de Tempo'!$F$5:$F$2004,A14,'Levantamento de Tempo'!$H$5:$H$2004,"S")/B14) -> 0 | F14: =C14*$B$6 -> 0
A15: 6. Atendimento e envio ao cliente | B15: =SUMIFS('Levantamento de Tempo'!$G$5:$G$2004,'Levantamento de Tempo'!$F$5:$F$2004,A15) -> 0 | C15: =B15/60 -> 0 | D15: =IF($B$17=0,0,B15/$B$17) -> 0 | E15: =IF(B15=0,0,SUMIFS('Levantamento de Tempo'!$G$5:$G$2004,'Levantamento de Tempo'!$F$5:$F$2004,A15,'Levantamento de Tempo'!$H$5:$H$2004,"S")/B15) -> 0 | F15: =C15*$B$6 -> 0
A16: 7. Outros | B16: =SUMIFS('Levantamento de Tempo'!$G$5:$G$2004,'Levantamento de Tempo'!$F$5:$F$2004,A16) -> 0 | C16: =B16/60 -> 0 | D16: =IF($B$17=0,0,B16/$B$17) -> 0 | E16: =IF(B16=0,0,SUMIFS('Levantamento de Tempo'!$G$5:$G$2004,'Levantamento de Tempo'!$F$5:$F$2004,A16,'Levantamento de Tempo'!$H$5:$H$2004,"S")/B16) -> 0 | F16: =C16*$B$6 -> 0
A17: Total | B17: =SUM(B10:B16) -> 45 | C17: =SUM(C10:C16) -> 0.75 | D17: =SUM(D10:D16) -> 1 | E17: =IF(B17=0,0,SUMIFS('Levantamento de Tempo'!$G$5:$G$2004,'Levantamento de Tempo'!$H$5:$H$2004,"S")/B17) -> 1 | F17: =SUM(F10:F16) -> 1.575
A19: Tempo por analista
A20: Analista (da aba Equipe) | B20: Horas no período | C20: Empresas na carteira | D20: Horas/empresa/mês
A21: =IF(Equipe!A5="","",Equipe!A5) -> Maria Exemplo (EXEMPLO) | B21: =IF(A21="","",SUMIFS('Levantamento de Tempo'!$G$5:$G$2004,'Levantamento de Tempo'!$B$5:$B$2004,A21)/60) -> 0.75 | C21: =IF(A21="","",COUNTIF('Cadastro Mestre'!$R$5:$R$504,A21)) -> 1 | D21: =IF(A21="","",IF(C21=0,"-",B21*$B$6/C21)) -> 1.575
A22: =IF(Equipe!A6="","",Equipe!A6) | B22: =IF(A22="","",SUMIFS('Levantamento de Tempo'!$G$5:$G$2004,'Levantamento de Tempo'!$B$5:$B$2004,A22)/60) | C22: =IF(A22="","",COUNTIF('Cadastro Mestre'!$R$5:$R$504,A22)) | D22: =IF(A22="","",IF(C22=0,"-",B22*$B$6/C22))
A23: =IF(Equipe!A7="","",Equipe!A7) | B23: =IF(A23="","",SUMIFS('Levantamento de Tempo'!$G$5:$G$2004,'Levantamento de Tempo'!$B$5:$B$2004,A23)/60) | C23: =IF(A23="","",COUNTIF('Cadastro Mestre'!$R$5:$R$504,A23)) | D23: =IF(A23="","",IF(C23=0,"-",B23*$B$6/C23))
A24: =IF(Equipe!A8="","",Equipe!A8) | B24: =IF(A24="","",SUMIFS('Levantamento de Tempo'!$G$5:$G$2004,'Levantamento de Tempo'!$B$5:$B$2004,A24)/60) | C24: =IF(A24="","",COUNTIF('Cadastro Mestre'!$R$5:$R$504,A24)) | D24: =IF(A24="","",IF(C24=0,"-",B24*$B$6/C24))
A25: =IF(Equipe!A9="","",Equipe!A9) | B25: =IF(A25="","",SUMIFS('Levantamento de Tempo'!$G$5:$G$2004,'Levantamento de Tempo'!$B$5:$B$2004,A25)/60) | C25: =IF(A25="","",COUNTIF('Cadastro Mestre'!$R$5:$R$504,A25)) | D25: =IF(A25="","",IF(C25=0,"-",B25*$B$6/C25))
A26: =IF(Equipe!A10="","",Equipe!A10) | B26: =IF(A26="","",SUMIFS('Levantamento de Tempo'!$G$5:$G$2004,'Levantamento de Tempo'!$B$5:$B$2004,A26)/60) | C26: =IF(A26="","",COUNTIF('Cadastro Mestre'!$R$5:$R$504,A26)) | D26: =IF(A26="","",IF(C26=0,"-",B26*$B$6/C26))
A27: =IF(Equipe!A11="","",Equipe!A11) | B27: =IF(A27="","",SUMIFS('Levantamento de Tempo'!$G$5:$G$2004,'Levantamento de Tempo'!$B$5:$B$2004,A27)/60) | C27: =IF(A27="","",COUNTIF('Cadastro Mestre'!$R$5:$R$504,A27)) | D27: =IF(A27="","",IF(C27=0,"-",B27*$B$6/C27))
A28: =IF(Equipe!A12="","",Equipe!A12) | B28: =IF(A28="","",SUMIFS('Levantamento de Tempo'!$G$5:$G$2004,'Levantamento de Tempo'!$B$5:$B$2004,A28)/60) | C28: =IF(A28="","",COUNTIF('Cadastro Mestre'!$R$5:$R$504,A28)) | D28: =IF(A28="","",IF(C28=0,"-",B28*$B$6/C28))
A29: =IF(Equipe!A13="","",Equipe!A13) | B29: =IF(A29="","",SUMIFS('Levantamento de Tempo'!$G$5:$G$2004,'Levantamento de Tempo'!$B$5:$B$2004,A29)/60) | C29: =IF(A29="","",COUNTIF('Cadastro Mestre'!$R$5:$R$504,A29)) | D29: =IF(A29="","",IF(C29=0,"-",B29*$B$6/C29))
A30: =IF(Equipe!A14="","",Equipe!A14) | B30: =IF(A30="","",SUMIFS('Levantamento de Tempo'!$G$5:$G$2004,'Levantamento de Tempo'!$B$5:$B$2004,A30)/60) | C30: =IF(A30="","",COUNTIF('Cadastro Mestre'!$R$5:$R$504,A30)) | D30: =IF(A30="","",IF(C30=0,"-",B30*$B$6/C30))
A31: =IF(Equipe!A15="","",Equipe!A15) | B31: =IF(A31="","",SUMIFS('Levantamento de Tempo'!$G$5:$G$2004,'Levantamento de Tempo'!$B$5:$B$2004,A31)/60) | C31: =IF(A31="","",COUNTIF('Cadastro Mestre'!$R$5:$R$504,A31)) | D31: =IF(A31="","",IF(C31=0,"-",B31*$B$6/C31))
A32: =IF(Equipe!A16="","",Equipe!A16) | B32: =IF(A32="","",SUMIFS('Levantamento de Tempo'!$G$5:$G$2004,'Levantamento de Tempo'!$B$5:$B$2004,A32)/60) | C32: =IF(A32="","",COUNTIF('Cadastro Mestre'!$R$5:$R$504,A32)) | D32: =IF(A32="","",IF(C32=0,"-",B32*$B$6/C32))
... A40: =IF(Equipe!A24="","",Equipe!A24) | B40: =IF(A40="","",SUMIFS('Levantamento de Tempo'!$G$5:$G$2004,'Levantamento de Tempo'!$B$5:$B$2004,A40)/60) | C40: =IF(A40="","",COUNTIF('Cadastro Mestre'!$R$5:$R$504,A40)) | D40: =IF(A40="","",IF(C40=0,"-",B40*$B$6/C40))
A42: Tempo por classe de empresa
A43: Classe | B43: Nº de empresas | C43: Horas no período | D43: Horas/empresa/mês
A44: A | B44: =COUNTIF('Cadastro Mestre'!$Q$5:$Q$504,A44) -> 0 | C44: =SUMIFS('Levantamento de Tempo'!$G$5:$G$2004,'Levantamento de Tempo'!$E$5:$E$2004,A44)/60 -> 0 | D44: =IF(B44=0,"-",C44*$B$6/B44) -> -
A45: B | B45: =COUNTIF('Cadastro Mestre'!$Q$5:$Q$504,A45) -> 1 | C45: =SUMIFS('Levantamento de Tempo'!$G$5:$G$2004,'Levantamento de Tempo'!$E$5:$E$2004,A45)/60 -> 0.75 | D45: =IF(B45=0,"-",C45*$B$6/B45) -> 1.575
A46: C | B46: =COUNTIF('Cadastro Mestre'!$Q$5:$Q$504,A46) -> 0 | C46: =SUMIFS('Levantamento de Tempo'!$G$5:$G$2004,'Levantamento de Tempo'!$E$5:$E$2004,A46)/60 -> 0 | D46: =IF(B46=0,"-",C46*$B$6/B46) -> -
A48: Leitura: horas/empresa/mês por classe é o principal KPI do projeto. A meta de 12 meses é reduzi-lo em ~30%.

Sheet Business Case
A1: Business Case — automação do departamento fiscal
A2: Texto azul com fundo amarelo = premissa editável (estimativa inicial). Texto preto = fórmula. Texto verde = vínculo.
A4: Premissas da equipe
A5: Analistas fiscais (nº) | B5: 12
A6: Custo mensal médio por analista: salário + encargos + benefícios (R$) | B6: 5500 | C6: =Equipe!$D$26 -> 0 | D6: ← média da aba Equipe (se preenchida)
A7: Horas produtivas por analista por mês | B7: 140
A8: Cenário de automação | B8: Base
A10: Onde está o tempo e quanto pode ser automatizado em 12 meses
A11: Etapa | B11: % do tempo (premissa) | C11: % medido (Resumo Baseline) | D11: Conservador | E11: Base | F11: Otimista | G11: Potencial no cenário | H11: Horas liberadas/mês
A12: 1. Coleta e cobrança de documentos | B12: 0.14 | C12: ='Resumo Baseline'!D10 -> 0 | D12: 0.35 | E12: 0.5 | F12: 0.65 | G12: =INDEX(D12:F12,1,MATCH($B$8,$D$11:$F$11,0)) -> 0.5 | H12: =$B$5*$B$7*B12*G12 -> 117.6
A13: 2. Importação e escrituração | B13: 0.32 | C13: ='Resumo Baseline'!D11 -> 1 | D13: 0.18 | E13: 0.25 | F13: 0.35 | G13: =INDEX(D13:F13,1,MATCH($B$8,$D$11:$F$11,0)) -> 0.25 | H13: =$B$5*$B$7*B13*G13 -> 134.4
A14: 3. Conferência e auditoria | B14: 0.11 | C14: ='Resumo Baseline'!D12 -> 0 | D14: 0.3 | E14: 0.45 | F14: 0.55 | G14: =INDEX(D14:F14,1,MATCH($B$8,$D$11:$F$11,0)) -> 0.45 | H14: =$B$5*$B$7*B14*G14 -> 83.16
A15: 4. Apuração e guias | B15: 0.12 | C15: ='Resumo Baseline'!D13 -> 0 | D15: 0.15 | E15: 0.25 | F15: 0.35 | G15: =INDEX(D15:F15,1,MATCH($B$8,$D$11:$F$11,0)) -> 0.25 | H15: =$B$5*$B$7*B15*G15 -> 50.4
A16: 5. Obrigações acessórias | B16: 0.12 | C16: ='Resumo Baseline'!D14 -> 0 | D16: 0.1 | E16: 0.15 | F16: 0.2 | G16: =INDEX(D16:F16,1,MATCH($B$8,$D$11:$F$11,0)) -> 0.15 | H16: =$B$5*$B$7*B16*G16 -> 30.24
A17: 6. Atendimento e envio ao cliente | B17: 0.11 | C17: ='Resumo Baseline'!D15 -> 0 | D17: 0.2 | E17: 0.3 | F17: 0.4 | G17: =INDEX(D17:F17,1,MATCH($B$8,$D$11:$F$11,0)) -> 0.3 | H17: =$B$5*$B$7*B17*G17 -> 55.44
A18: 7. Outros | B18: 0.08 | C18: ='Resumo Baseline'!D16 -> 0 | D18: 0 | E18: 0 | F18: 0 | G18: =INDEX(D18:F18,1,MATCH($B$8,$D$11:$F$11,0)) -> 0 | H18: =$B$5*$B$7*B18*G18 -> 0
A19: Total / ganho ponderado | B19: =SUM(B12:B18) -> 1 | C19: =SUM(C12:C18) -> 1 | D19: =SUMPRODUCT($B$12:$B$18,D12:D18) -> 0.1916 | E19: =SUMPRODUCT($B$12:$B$18,E12:E18) -> 0.2805 | F19: =SUMPRODUCT($B$12:$B$18,F12:F18) -> 0.3735 | G19: =SUMPRODUCT(B12:B18,G12:G18) -> 0.2805 | H19: =SUM(H12:H18) -> 471.24
A20: Checagem da soma dos % do tempo | B20: =IF(ABS(B19-1)<0.001,"OK","Ajuste: soma ≠ 100%") -> OK
A21: Quando o levantamento terminar, copie os % da coluna C para a coluna B.
A23: Custos e receitas do ecossistema
A24: Analista de automação/dados: custo mensal (R$) | B24: 7500
A25: Ferramentas e licenças: captura de XML, workflow, BI (R$/mês) | B25: 2500
A26: Infraestrutura: servidor ou nuvem, banco, backup (R$/mês) | B26: 800
A27: APIs e IA: Integra Contador, Claude (R$/mês) | B27: 800
A28: Nova receita com serviços habilitados: recuperação de monofásico, revisão de regime (R$/mês) | B28: 0
A29: Implantação: consultoria/desenvolvimento externo, valor único (R$) | B29: 40000
A30: Meses para diluir a implantação | B30: 4
A32: Rampa de ganho (% do ganho pleno alcançado)
A33: Meses 1 a 3 (Fase 0 e início da Fase 1) | B33: 0.1
A34: Meses 4 a 6 | B34: 0.4
A35: Meses 7 a 9 | B35: 0.7
A36: Mês 10 em diante | B36: 1
A38: Resultado
A39: Ganho de produtividade ponderado (cenário escolhido) | B39: =G19 -> 0.2805
A40: Horas liberadas por mês em regime pleno | B40: =H19 -> 471.24
A41: FTE equivalente liberado | B41: =IF($B$7=0,0,B40/$B$7) -> 3.366
A42: Economia bruta anual se a capacidade virar não reposição de vagas (R$) | B42: =B41*$B$6*12 -> 222156
A43: Nova receita anual (R$) | B43: =$B$28*12 -> 0
A44: Custo recorrente anual do ecossistema (R$) | B44: =($B$24+$B$25+$B$26+$B$27)*12 -> 139200
A45: Resultado líquido anual em regime pleno (R$) | B45: =B42+B43-B44 -> 82956
...

Sheet Catálogo de Auditorias
A1: Catálogo de Auditorias Fiscais (regras AUD)
A2: Prioridade = risco × 2 + (4 − esforço): de 3 a 9, quanto maior, antes. Status e responsável servem para acompanhar a construção.
A4: Código | B4: Grupo | C4: Regra | D4: O que verifica | E4: Fontes cruzadas | F4: Regimes | G4: Tributos | H4: Risco | I4: Esforço | J4: Fase | K4: Frequência | L4: Ação | M4: Referência | N4: Prioridade | O4: Status | P4: Responsável | Q4: Observações
A5: AUD-A01 | B5: A. Completude documental | C5: NF-e de entrada não escrituradas | D5: Toda NF-e emitida contra o CNPJ do cliente (Distribuição DF-e / manifestação) está escriturada na competência; lista faltantes. | E5: XML (SEFAZ) × escrituração Domínio | F5: Todos | G5: ICMS, IPI, PIS/COFINS | H5: Alto | I5: Baixo | J5: 1 | K5: Diária/mensal | L5: Bloqueia | N5: =IF(H5="Alto",3,IF(H5="Médio",2,1))*2+4-IF(I5="Alto",3,IF(I5="Médio",2,1)) -> 9 | O5: Backlog
A6: AUD-A02 | B6: A. Completude documental | C6: Notas de saída não escrituradas | D6: NF-e/NFC-e autorizadas do cliente × escrituração: faltantes, extras e total por dia/série. | E6: XML emitidos (autXML/ERP/captura) × escrituração | F6: Todos | G6: Todos | H6: Alto | I6: Baixo | J6: 1 | K6: Mensal | L6: Bloqueia | N6: =IF(H6="Alto",3,IF(H6="Médio",2,1))*2+4-IF(I6="Alto",3,IF(I6="Médio",2,1)) -> 9 | O6: Backlog
A7: AUD-A03 | B7: A. Completude documental | C7: Canceladas, denegadas e inutilizadas | D7: Nota cancelada escriturada como normal, cancelamento posterior ao lançamento e inutilizações sem registro de situação. | E7: Eventos SEFAZ × escrituração | F7: Todos | G7: Todos | H7: Alto | I7: Baixo | J7: 1 | K7: Mensal | L7: Bloqueia | N7: =IF(H7="Alto",3,IF(H7="Médio",2,1))*2+4-IF(I7="Alto",3,IF(I7="Médio",2,1)) -> 9 | O7: Backlog
A8: AUD-A04 | B8: A. Completude documental | C8: Quebra de sequência numérica | D8: Saltos na numeração das notas emitidas (por modelo/série) sem inutilização correspondente. | E8: XML emitidos × eventos de inutilização | F8: Todos | G8: Todos | H8: Médio | I8: Baixo | J8: 2 | K8: Mensal | L8: Alerta | N8: =IF(H8="Alto",3,IF(H8="Médio",2,1))*2+4-IF(I8="Alto",3,IF(I8="Médio",2,1)) -> 7 | O8: Backlog
A9: AUD-A05 | B9: A. Completude documental | C9: Lançamento em duplicidade | D9: Mesma chave de acesso (ou emitente + número + série) escriturada mais de uma vez. | E9: Escrituração Domínio | F9: Todos | G9: Todos | H9: Alto | I9: Baixo | J9: 1 | K9: Mensal | L9: Bloqueia | N9: =IF(H9="Alto",3,IF(H9="Médio",2,1))*2+4-IF(I9="Alto",3,IF(I9="Médio",2,1)) -> 9 | O9: Backlog
A10: AUD-A06 | B10: A. Completude documental | C10: NFS-e prestadas e tomadas não escrituradas | D10: NFS-e do Ambiente Nacional (API do ADN por NSU, com certificado) e de prefeituras que não compartilham × escrituração de serviços, com retenções. | E10: ADN / prefeituras × escrituração | F10: Todos | G10: ISS, IRRF, CSRF, INSS | H10: Alto | I10: Médio | J10: 1 | K10: Mensal | L10: Bloqueia | M10: LC 214/2025, art. 62; Res. CGSN 191/2026 | N10: =IF(H10="Alto",3,IF(H10="Médio",2,1))*2+4-IF(I10="Alto",3,IF(I10="Médio",2,1)) -> 8 | O10: Backlog
A11: AUD-A07 | B11: A. Completude documental | C11: CT-e tomados não escriturados | D11: CT-e em que o cliente é tomador × escrituração; vínculo CT-e ↔ NF-e (frete FOB) e crédito do frete. | E11: XML CT-e × escrituração | F11: Todos | G11: ICMS, PIS/COFINS | H11: Médio | I11: Médio | J11: 2 | K11: Mensal | L11: Alerta | N11: =IF(H11="Alto",3,IF(H11="Médio",2,1))*2+4-IF(I11="Alto",3,IF(I11="Médio",2,1)) -> 6 | O11: Backlog
A12: AUD-A08 | B12: A. Completude documental | C12: Notas não reconhecidas pelo cliente | D12: NF-e contra o CNPJ sem manifestação ou de fornecedor atípico: possível nota fria ou operação não realizada. | E12: Distribuição DF-e × manifestação × histórico de fornecedores | F12: Todos | G12: ICMS, PIS/COFINS | H12: Médio | I12: Médio | J12: 3 | K12: Semanal | L12: Alerta | N12: =IF(H12="Alto",3,IF(H12="Médio",2,1))*2+4-IF(I12="Alto",3,IF(I12="Médio",2,1)) -> 6 | O12: Backlog
A13: AUD-A09 | B13: A. Completude documental | C13: "Sem movimento" com documentos | D13: Empresa marcada sem movimento ou com apuração zerada, mas com XML emitido/recebido na competência. | E13: Cadastro mestre × XML × apuração | F13: Todos | G13: Todos | H13: Alto | I13: Baixo | J13: 1 | K13: Mensal | L13: Bloqueia | N13: =IF(H13="Alto",3,IF(H13="Médio",2,1))*2+4-IF(I13="Alto",3,IF(I13="Médio",2,1)) -> 9 | O13: Backlog
A14: AUD-B01 | B14: B. Integridade de valores | C14: Totais do documento divergentes | D14: Valor contábil, BC e ICMS, BC e ICMS-ST, IPI, PIS, COFINS e FCP: XML × escrituração, por chave, com tolerância. | E14: XML × escrituração (relatório/EFD C100-C190) | F14: Todos | G14: ICMS, ST, IPI, PIS/COFINS | H14: Alto | I14: Baixo | J14: 1 | K14: Mensal | L14: Bloqueia | N14: =IF(H14="Alto",3,IF(H14="Médio",2,1))*2+4-IF(I14="Alto",3,IF(I14="Médio",2,1)) -> 9 | O14: Backlog
A15: AUD-B02 | B15: B. Integridade de valores | C15: Competência e datas | D15: Data de entrada/saída fora da competência; notas extemporâneas lançadas sem controle. | E15: XML × escrituração | F15: Todos | G15: Todos | H15: Médio | I15: Baixo | J15: 1 | K15: Mensal | L15: Alerta | N15: =IF(H15="Alto",3,IF(H15="Médio",2,1))*2+4-IF(I15="Alto",3,IF(I15="Médio",2,1)) -> 7 | O15: Backlog
A16: AUD-B03 | B16: B. Integridade de valores | C16: Participante divergente | D16: CNPJ, IE e UF do participante no cadastro da Domínio × XML (afeta CFOP interno/interestadual e DIFAL). | E16: XML × cadastro de participantes | F16: Todos | G16: ICMS | H16: Médio | I16: Baixo | J16: 2 | K16: Mensal | L16: Alerta | N16: =IF(H16="Alto",3,IF(H16="Médio",2,1))*2+4-IF(I16="Alto",3,IF(I16="Médio",2,1)) -> 7 | O16: Backlog
A17: AUD-B04 | B17: B. Integridade de valores | C17: Itens divergentes nas entradas | D17: Quantidade, valor, NCM e CFOP por item: XML × registro de itens (EFD C170). | E17: XML × EFD ICMS/IPI (C170) | F17: LP, LR | G17: ICMS, IPI, PIS/COFINS | H17: Médio | I17: Médio | J17: 3 | K17: Mensal | L17: Alerta | N17: =IF(H17="Alto",3,IF(H17="Médio",2,1))*2+4-IF(I17="Alto",3,IF(I17="Médio",2,1)) -> 6 | O17: Backlog
A18: AUD-C01 | B18: C. Classificação fiscal | C18: CFOP de entrada incoerente | D18: CFOP escriturado × CFOP do emitente e finalidade (ex.: 5405→1403/1407; 6102→2102/2556/2551; 5910→1910; 5202→1202) e 1º dígito × UF. | E18: XML × escrituração × tabela de conversão | F18: Todos | G18: ICMS, PIS/COFINS | H18: Alto | I18: Médio | J18: 1 | K18: Mensal | L18: Bloqueia | M18: Convênio s/nº 1970 (CFOP) | N18: =IF(H18="Alto",3,IF(H18="Médio",2,1))*2+4-IF(I18="Alto",3,IF(I18="Médio",2,1)) -> 8 | O18: Backlog
A19: AUD-C02 | B19: C. Classificação fiscal | C19: CFOP × CST/CSOSN incoerentes | D19: Ex.: 5405 com CST 00; CST 40/41 com ICMS destacado; CST 60 sem CFOP de ST; CSOSN em empresa do regime normal e CST em optante do Simples. | E19: XML × escrituração × cadastro mestre | F19: Todos | G19: ICMS | H19: Alto | I19: Baixo | J19: 1 | K19: Mensal | L19: Bloqueia | N19: =IF(H19="Alto",3,IF(H19="Médio",2,1))*2+4-IF(I19="Alto",3,IF(I19="Médio",2,1)) -> 9 | O19: Backlog
A20: AUD-C03 | B20: C. Classificação fiscal | C20: Crédito de ICMS indevido ou não aproveitado | D20: Crédito em uso e consumo, ativo fora do CIAP (1/48), fornecedor do Simples sem pCredSN, entradas com ST/isentas; e créditos permitidos não aproveitados. | E20: XML × escrituração × finalidade do item | F20: LP, LR | G20: ICMS | H20: Alto | I20: Médio | J20: 2 | K20: Mensal | L20: Bloqueia | M20: LC 87/1996, arts. 20 e 33; LC 123/2006, art. 23 | N20: =IF(H20="Alto",3,IF(H20="Médio",2,1))*2+4-IF(I20="Alto",3,IF(I20="Médio",2,1)) -> 8 | O20: Backlog
A21: AUD-C04 | B21: C. Classificação fiscal | C21: Créditos de PIS/COFINS não cumulativos | D21: CST 50–56 nas entradas × natureza do item (insumo, revenda, ativo); monofásicos e alíquota zero sem crédito; coerência com EFD-Contribuições. | E21: XML × escrituração × EFD-Contribuições | F21: LR | G21: PIS/COFINS | H21: Alto | I21: Alto | J21: 3 | K21: Mensal | L21: Alerta | M21: Leis 10.637/2002 e 10.833/2003 (até 12/2026; revisão retroativa 5 anos) | N21: =IF(H21="Alto",3,IF(H21="Médio",2,1))*2+4-IF(I21="Alto",3,IF(I21="Médio",2,1)) -> 7 | O21: Backlog
A22: AUD-C05 | B22: C. Classificação fiscal | C22: Monofásicos de PIS/COFINS | D22: NCM na lista de tributação concentrada × receita segregada no PGDAS-D (Simples) ou CST 04 nas saídas (LP/LR). Pagamento em duplicidade vira recuperação. | E22: XML (NCM) × tabela de monofásicos × PGDAS-D/escrituração | F22: SN, LP, LR | G22: PIS/COFINS | H22: Alto | I22: Médio | J22: 1 | K22: Mensal | L22: Oportunidade | M22: Leis 10.147/2000, 10.485/2002, 13.097/2015; LC 123/2006, art. 18 §4º-A | N22: =IF(H22="Alto",3,IF(H22="Médio",2,1))*2+4-IF(I22="Alto",3,IF(I22="Médio",2,1)) -> 8 | O22: Backlog
A23: AUD-C06 | B23: C. Classificação fiscal | C23: ICMS-ST: produto sujeito × tratamento | D23: NCM/CEST sujeito à ST na UF × CST/CSOSN e segregação de receita com ST no Simples; ST não retida em compra interestadual. | E23: XML × tabela ST por UF × escrituração/PGDAS-D | F23: Todos | G23: ICMS-ST | H23: Alto | I23: Alto | J23: 3 | K23: Mensal | L23: Alerta | M23: Convênios/protocolos ICMS e legislação da UF | N23: =IF(H23="Alto",3,IF(H23="Médio",2,1))*2+4-IF(I23="Alto",3,IF(I23="Médio",2,1)) -> 7 | O23: Backlog
A24: AUD-C07 | B24: C. Classificação fiscal | C24: DIFAL | D24: Compras interestaduais para uso/consumo/ativo e vendas a não contribuinte de outra UF: DIFAL calculado e recolhido. | E24: XML × escrituração × guias | F24: Todos | G24: ICMS DIFAL/FCP | H24: Alto | I24: Médio | J24: 2 | K24: Mensal | L24: Alerta | M24: EC 87/2015; LC 190/2022 | N24: =IF(H24="Alto",3,IF(H24="Médio",2,1))*2+4-IF(I24="Alto",3,IF(I24="Médio",2,1)) -> 8 | O24: Backlog
A25: AUD-C08 | B25: C. Classificação fiscal | C25: Alíquota de IPI × TIPI | D25: Indústrias e equiparadas: alíquota por NCM × TIPI vigente; crédito de IPI nas entradas. | E25: XML × TIPI × escrituração | F25: LP, LR | G25: IPI | H25: Médio | I25: Médio | J25: 3 | K25: Mensal | L25: Alerta | M25: Decreto 11.158/2022 (TIPI) e alterações | N25: =IF(H25="Alto",3,IF(H25="Médio",2,1))*2+4-IF(I25="Alto",3,IF(I25="Médio",2,1)) -> 6 | O25: Backlog
A26: AUD-C09 | B26: C. Classificação fiscal | C26: NCM inválido ou incompatível | D26: NCM inexistente/expirado ou incompatível com a descrição do produto (triagem assistida por IA, decisão humana). | E26: XML × tabela NCM × IA | F26: Todos | G26: Todos | H26: Médio | I26: Médio | J26: 3 | K26: Mensal | L26: Alerta | N26: =IF(H26="Alto",3,IF(H26="Médio",2,1))*2+4-IF(I26="Alto",3,IF(I26="Médio",2,1)) -> 6 | O26: Backlog
A27: AUD-C10 | B27: C. Classificação fiscal | C27: Antecipação de ICMS (conforme UF) | D27: Entradas interestaduais sujeitas à antecipação parcial/total × guia recolhida. | E27: XML × regra da UF × guias | F27: Todos | G27: ICMS | H27: Médio | I27: Alto | J27: 3 | K27: Mensal | L27: Alerta | M27: Legislação da UF | N27: =IF(H27="Alto",3,IF(H27="Médio",2,1))*2+4-IF(I27="Alto",3,IF(I27="Médio",2,1)) -> 5 | O27: Backlog
A28: AUD-C11 | B28: C. Classificação fiscal | C28: Reforma: grupos IBS/CBS nos documentos | D28: CST IBS/CBS, cClassTrib, bases e alíquotas nos XML emitidos (obrigatório: NF-e/CT-e desde 03/08/2026, NFS-e desde 01/10/2026, Simples em 01/01/2027). A SEFAZ ainda não rejeita a falta do grupo: só a auditoria pega. | E28: XML × tabelas da RTC × escrituração | F28: Todos | G28: CBS, IBS | H28: Alto | I28: Médio | J28: 1 | K28: Mensal | L28: Alerta | M28: LC 214/2025; Ato Conjunto RFB/CGIBS 4/2026; NT 2025.002-RTC | N28: =IF(H28="Alto",3,IF(H28="Médio",2,1))*2+4-IF(I28="Alto",3,IF(I28="Médio",2,1)) -> 8 | O28: Backlog
A29: AUD-D01 | B29: D. Apuração (recálculo-sombra) | C29: Simples Nacional: recálculo do DAS | D29: Recalcula RBT12, anexo, faixa, alíquota efetiva e repartição, com segregações (ST, monofásico, exportação, ISS retido) × Domínio × PGDAS-D. | E29: Receitas × tabelas LC 123 × Domínio × PGDAS-D | F29: SN | G29: DAS | H29: Alto | I29: Médio | J29: 1 | K29: Mensal | L29: Bloqueia | M29: LC 123/2006; Res. CGSN 140/2018 | N29: =IF(H29="Alto",3,IF(H29="Médio",2,1))*2+4-IF(I29="Alto",3,IF(I29="Médio",2,1)) -> 8 | O29: Backlog
A30: AUD-D02 | B30: D. Apuração (recálculo-sombra) | C30: Simples Nacional: limite e sublimite | D30: Receita acumulada e RBT12 × sublimite (R$ 3,6 mi) e limite (R$ 4,8 mi); alerta preventivo a partir de 80%. | E30: Receitas 12 meses | F30: SN | G30: DAS, ICMS, ISS | H30: Alto | I30: Baixo | J30: 1 | K30: Mensal | L30: Alerta | M30: LC 123/2006, arts. 3º e 13-A | N30: =IF(H30="Alto",3,IF(H30="Médio",2,1))*2+4-IF(I30="Alto",3,IF(I30="Médio",2,1)) -> 9 | O30: Backlog
A31: AUD-D03 | B31: D. Apuração (recálculo-sombra) | C31: Simples Nacional: Fator R | D31: Folha de 12 meses (salários, pró-labore, FGTS, CPP) ÷ RBT12 ≥ 28% define Anexo III × V; confere o anexo aplicado. | E31: Domínio Folha × receitas × apuração | F31: SN | G31: DAS | H31: Alto | I31: Médio | J31: 2 | K31: Mensal | L31: Bloqueia | M31: LC 123/2006, art. 18 (fator r) | N31: =IF(H31="Alto",3,IF(H31="Médio",2,1))*2+4-IF(I31="Alto",3,IF(I31="Médio",2,1)) -> 8 | O31: Backlog
A32: AUD-D04 | B32: D. Apuração (recálculo-sombra) | C32: Lucro Presumido: IRPJ e CSLL | D32: Base de presunção por atividade, acréscimo de 10% nos percentuais sobre a receita acima de R$ 5 mi/ano (R$ 1,25 mi/trimestre; IRPJ desde 01/2026, CSLL desde 04/2026), adicional de IRPJ e retenções compensadas. | E32: Receitas por atividade × apuração Domínio × DCTFWeb/MIT | F32: LP | G32: IRPJ, CSLL | H32: Alto | I32: Médio | J32: 2 | K32: Trimestral | L32: Bloqueia | M32: Lei 9.249/1995, arts. 15 e 20; LC 224/2025; IN RFB 2.305/2025 e 2.306/2026 | N32: =IF(H32="Alto",3,IF(H32="Médio",2,1))*2+4-IF(I32="Alto",3,IF(I32="Médio",2,1)) -> 8 | O32: Backlog
A33: AUD-D05 | B33: D. Apuração (recálculo-sombra) | C33: PIS/COFINS: débitos e créditos | D33: Recalcula débitos (cumulativo 0,65%/3%; não cumulativo 1,65%/7,6%), exclusões e créditos × apuração × EFD-Contribuições, incluindo a redução de benefícios da LC 224/2025 (até 12/2026; depois, revisão retroativa). | E33: Escrituração × EFD-Contribuições | F33: LP, LR | G33: PIS/COFINS | H33: Alto | I33: Médio | J33: 3 | K33: Mensal | L33: Alerta | M33: Leis 9.718/1998, 10.637/2002 e 10.833/2003; LC 224/2025 | N33: =IF(H33="Alto",3,IF(H33="Médio",2,1))*2+4-IF(I33="Alto",3,IF(I33="Médio",2,1)) -> 8 | O33: Backlog
A34: AUD-D06 | B34: D. Apuração (recálculo-sombra) | C34: ICMS regime normal: apuração | D34: Recalcula débitos e créditos pelos documentos (C190) × apuração da Domínio (E110) × declaração estadual; saldo credor transportado. | E34: EFD ICMS/IPI × apuração × GIA/declaração da UF | F34: LP, LR | G34: ICMS | H34: Alto | I34: Médio | J34: 2 | K34: Mensal | L34: Bloqueia | N34: =IF(H34="Alto",3,IF(H34="Médio",2,1))*2+4-IF(I34="Alto",3,IF(I34="Médio",2,1)) -> 8 | O34: Backlog
A35: AUD-D07 | B35: D. Apuração (recálculo-sombra) | C35: ISS próprio e retido | D35: ISS dos serviços prestados × alíquota e local de incidência; ISS retido por tomadores deduzido; ISS retido em serviços tomados recolhido. | E35: NFS-e × escrituração × guias municipais | F35: Todos | G35: ISS | H35: Médio | I35: Médio | J35: 2 | K35: Mensal | L35: Alerta | M35: LC 116/2003, arts. 3º e 6º | N35: =IF(H35="Alto",3,IF(H35="Médio",2,1))*2+4-IF(I35="Alto",3,IF(I35="Médio",2,1)) -> 6 | O35: Backlog
A36: AUD-D08 | B36: D. Apuração (recálculo-sombra) | C36: Retenções federais e INSS | D36: Serviços tomados e prestados com IRRF, CSRF (4,65%) e INSS (11%) × EFD-Reinf (R-2010/R-2020/R-4020) × DCTFWeb. | E36: NFS-e × escrituração × EFD-Reinf × DCTFWeb | F36: Todos | G36: IRRF, CSRF, INSS | H36: Alto | I36: Médio | J36: 2 | K36: Mensal | L36: Bloqueia | M36: Lei 10.833/2003, art. 30; Lei 8.212/1991, art. 31 | N36: =IF(H36="Alto",3,IF(H36="Médio",2,1))*2+4-IF(I36="Alto",3,IF(I36="Médio",2,1)) -> 8 | O36: Backlog
A37: AUD-D09 | B37: D. Apuração (recálculo-sombra) | C37: Carga tributária fora do padrão | D37: Carga efetiva do mês (tributos ÷ receita) × média de 12 meses e faixa esperada do segmento. | E37: Apurações × receitas (histórico) | F37: Todos | G37: Todos | H37: Médio | I37: Baixo | J37: 3 | K37: Mensal | L37: Alerta | N37: =IF(H37="Alto",3,IF(H37="Médio",2,1))*2+4-IF(I37="Alto",3,IF(I37="Médio",2,1)) -> 7 | O37: Backlog
A38: AUD-D10 | B38: D. Apuração (recálculo-sombra) | C38: Lucros e dividendos acima de R$ 50 mil/mês | D38: Pagamentos de lucros à mesma pessoa física acima de R$ 50 mil no mês: IRRF de 10% retido × EFD-Reinf (R-4010) × DCTFWeb. Interface com contábil/DP. | E38: Distribuições (contábil) × EFD-Reinf × DCTFWeb | F38: Todos | G38: IRRF | H38: Alto | I38: Baixo | J38: 2 | K38: Mensal | L38: Alerta | M38: Lei 15.270/2025; NT EFD-Reinf 02/2026 | N38: =IF(H38="Alto",3,IF(H38="Médio",2,1))*2+4-IF(I38="Alto",3,IF(I38="Médio",2,1)) -> 9 | O38: Backlog
A39: AUD-E01 | B39: E. Declarado × apurado × pago | C39: Apuração × declaração transmitida | D39: Valores da Domínio × PGDAS-D, DCTFWeb/MIT, EFD-Contribuições, EFD ICMS/IPI e declarações estaduais/municipais. | E39: Domínio × Integra Contador × recibos | F39: Todos | G39: Todos | H39: Alto | I39: Médio | J39: 2 | K39: Mensal | L39: Bloqueia | N39: =IF(H39="Alto",3,IF(H39="Médio",2,1))*2+4-IF(I39="Alto",3,IF(I39="Médio",2,1)) -> 8 | O39: Backlog
A40: AUD-E02 | B40: E. Declarado × apurado × pago | C40: Guia emitida × guia paga | D40: DAS, DARF e guias estaduais/municipais emitidas × pagamentos localizados; aviso ao cliente antes do vencimento. | E40: Guias × consulta de pagamentos (e-CAC) × conta corrente da UF | F40: Todos | G40: Todos | H40: Alto | I40: Médio | J40: 2 | K40: Mensal | L40: Alerta | N40: =IF(H40="Alto",3,IF(H40="Médio",2,1))*2+4-IF(I40="Alto",3,IF(I40="Médio",2,1)) -> 8 | O40: Backlog
A41: AUD-E03 | B41: E. Declarado × apurado × pago | C41: Obrigações entregues no prazo | D41: Matriz de obrigações de cada empresa × recibos de entrega; alerta 5 dias antes do vencimento. | E41: Cadastro mestre × recibos | F41: Todos | G41: Todos | H41: Alto | I41: Baixo | J41: 2 | K41: Diária | L41: Alerta | N41: =IF(H41="Alto",3,IF(H41="Médio",2,1))*2+4-IF(I41="Alto",3,IF(I41="Médio",2,1)) -> 9 | O41: Backlog
...

Sheet Plano 30 dias
A1: Plano da Fase 0 — 30 dias
A2: Informe a data de início (segunda-feira). Os prazos se ajustam sozinhos.
A4: Data de início (segunda-feira) | C4: 46293
A6: Semana | B6: Nº | C6: Ação | D6: Responsável (sugestão) | E6: Entregável | F6: Prazo | G6: Status | H6: Observações
A7: 1 | B7: 1 | C7: URGENTE (até 30/09/2026): revisar clientes do Simples com vendas relevantes para empresas e decidir a opção pelo IBS/CBS fora do DAS no 1º semestre de 2027. A opção pode ser cancelada até 30/11/2026. Confirme as regras no Portal do Simples Nacional. | D7: Sócio + coordenador | E7: Clientes analisados e opções feitas | F7: 46295 | G7: A fazer | H7: Prazo legal fixo
A8: 1 | B8: 2 | C8: Nomear o núcleo do projeto: patrocinador (sócio), dono das regras (coordenador fiscal) e candidato a analista de automação. | D8: Sócio | E8: Núcleo nomeado | F8: =$C$4+4+7*(A8-1) -> 46297 | G8: A fazer
A9: 1 | B9: 3 | C9: Comunicar a equipe: objetivos (qualidade, escala, menos retrabalho), como o tempo será medido e o compromisso com as pessoas. | D9: Sócio | E9: Reunião realizada | F9: =$C$4+4+7*(A9-1) -> 46297 | G9: A fazer
A10: 1 | B10: 4 | C10: Preencher a aba Equipe e iniciar o Levantamento de Tempo (10 dias úteis). | D10: Coordenador fiscal | E10: Registros diários | F10: =$C$4+4+7*(A10-1) -> 46297 | G10: A fazer
A11: 1 | B11: 5 | C11: Agendar reunião com o gerente de contas da Thomson Reuters (roteiro na aba Roteiro de Reuniões). | D11: Sócio | E11: Reunião agendada | F11: =$C$4+4+7*(A11-1) -> 46297 | G11: A fazer
A12: 2 | B12: 6 | C12: Preencher o Cadastro Mestre de 100% das empresas (cada analista, a sua carteira). | D12: Analistas | E12: Cadastro completo | F12: =$C$4+4+7*(A12-1) -> 46304 | G12: A fazer
A13: 2 | B13: 7 | C13: Inventariar certificados (A1/A3), procurações do e-CAC e acessos estaduais/municipais. | D13: Coordenador fiscal | E13: Pendências listadas | F13: =$C$4+4+7*(A13-1) -> 46304 | G13: A fazer
A14: 2 | B14: 8 | C14: Mapear o processo atual de 3 empresas-tipo: Simples comércio, Presumido serviços e regime normal de ICMS. | D14: Coordenador + 1 analista | E14: Fluxo atual desenhado | F14: =$C$4+4+7*(A14-1) -> 46304 | G14: A fazer
A15: 2 | B15: 9 | C15: Iniciar a campanha autXML: pedir aos clientes que incluam o CNPJ do escritório no campo autXML das NF-e que emitem. | D15: Coordenador + atendimento | E15: Comunicado enviado | F15: =$C$4+4+7*(A15-1) -> 46304 | G15: A fazer
A16: 2 | B16: 10 | C16: Reunião com a Thomson Reuters: registrar as respostas no roteiro. | D16: Sócio | E16: Roteiro respondido | F16: =$C$4+4+7*(A16-1) -> 46304 | G16: A fazer
A17: 3 | B17: 11 | C17: Pedir a chave da API da Domínio (api.dominio@tr.com), enviar XML de 1 empresa e testar a extração (EFD, Gerador de Relatórios e, se liberado, backup do banco). | D17: Analista de automação | E17: Envio e extração testados | F17: =$C$4+4+7*(A17-1) -> 46311 | G17: A fazer
A18: 3 | B18: 12 | C18: Contratar e testar o Integra Contador (SERPRO) com 2 empresas-piloto (procuração). | D18: Analista de automação | E18: Consulta PGDAS-D e caixa postal ok | F18: =$C$4+4+7*(A18-1) -> 46311 | G18: A fazer
A19: 3 | B19: 13 | C19: POCs: captura (2 parceiros homologados da API Domínio) e auditoria (Kolossus Auditor e 1 alternativa), usando o Catálogo de Auditorias como checklist de cobertura. | D19: Coordenador fiscal | E19: Comparativo preenchido | F19: =$C$4+4+7*(A19-1) -> 46311 | G19: A fazer
... A24: 4 | B24: 18 | C24: Aprovar o backlog da Fase 1 (16 regras) e o calendário de fechamento do piloto. | D24: Sócio + coordenador | E24: Kick-off da Fase 1 | F24: =$C$4+4+7*(A24-1) -> 46318 | G24: A fazer

Sheet Roteiro de Reuniões
A1: Roteiro de reuniões da Fase 0
A2: Perguntas que decidem a arquitetura. Registre a resposta e quem respondeu.
A4: Com quem | B4: Nº | C4: Pergunta | D4: Por que importa | E4: Resposta | F4: Respondido por / data
A5: Thomson Reuters | B5: 1 | C5: API Onvio BR Accounting (Integração com ERP): custo, limites de volume e como ativar a chave de integração em todas as empresas. As Rotinas Automáticas importam sem usuário logado na versão Web? | D5: É a porta oficial de entrada de XML na Escrita Fiscal, sem robô de tela.
A6: Thomson Reuters | B6: 2 | C6: Existe (ou está no roadmap) alguma API para LER dados: notas, itens, apurações, saldos? | D6: Hoje a API só envia dados para dentro da Domínio.
A7: Thomson Reuters | B7: 3 | C7: Podemos restaurar os backups do nosso banco (Suporte > Backup) em servidor próprio e ler via ODBC com usuário externo? Há exigência de licença do SQL Anywhere? Qual a frequência dos backups de modificações? | D7: É o caminho usado por fornecedores de BI para ter todos os dados da escrituração.
A8: Thomson Reuters | B8: 4 | C8: Leiaute Importação Padrão (TXT com separador): documentação atual; aceita acumulador e CFOP por nota? Funciona igual na versão Web? | D8: Permite lançar documentos sem XML ou com classificação definida pelo nosso motor.
A9: Thomson Reuters | B9: 5 | C9: Dá para gerar EFD e relatórios do Gerador de Relatórios em lote (várias empresas) e salvar em pasta mapeada? | D9: Plano B de extração se o backup não for liberado.
A10: Thomson Reuters | B10: 6 | C10: É permitido usar robôs (RPA) na Domínio Web? Exige usuário/licença dedicada? Como tratar o MFA do login? | D10: A Domínio Web é transmitida por imagem (GraphOn): robô de tela é frágil e precisa de regra clara.
A11: Thomson Reuters | B11: 7 | C11: Kolossus Auditor: quais cruzamentos cobre, custo por empresa, e se exporta os achados (Excel/API) para o nosso painel. | D11: Pode cobrir parte do catálogo sem desenvolvimento.
A12: Thomson Reuters | B12: 8 | C12: Domínio Processos e Portal do Cliente estão no nosso pacote (One/Pro/Max)? Como encerram tarefas automaticamente? | D12: Evita contratar outra ferramenta de workflow.
A13: Thomson Reuters | B13: 9 | C13: Cronograma da Domínio para CBS/IBS em 2026–2027: escrituração, apuração, Simples com IBS/CBS fora do DAS. | D13: A virada de janeiro/2027 muda regras e telas.
A14: Thomson Reuters | B14: 10 | C14: Como somos avisados de mudanças de tela ou de leiaute nas atualizações? | D14: Robôs e importações quebram com mudanças não avisadas.
A15: SERPRO | B15: 11 | C15: Integra Contador: confirmar os serviços do nosso caso (PGDAS-D, DEFIS, DCTFWeb/MIT, Caixa Postal, SITFIS, Pagamentos, Parcelamentos, Eventos de Atualização). | D15: Automatiza consultas e transmissões federais por API oficial.
A16: SERPRO | B16: 12 | C16: Tabela de preços vigente por faixa (consulta, emissão, declaração), contrato e prazo de ativação. | D16: Entra no Business Case.
... A22: Fornecedores de captura | B22: 18 | C22: Preço por empresa/volume, contrato, LGPD (acordo de tratamento de dados) e onde os dados ficam. | D22: Custo e conformidade.
